Workbook

Sheet README
A1: GCCN_5YR_Financial_Model.xlsx
A3: Sheets
A4: Assumptions — yellow INPUTS; C5 scenario toggle
A5: Annual_PnL — Y1–Y5 × Cons/Base/Upside + selected summary
A6: Monthly_Y1 — seasonality × Y1
A7: Unit_Economics — per-booking contribution
A9: Recommended model: asset-light marketplace ~12% Base (+~1.5pts owned/sister) take on GMV via owned Stripe; OTAs optional Channels only.
A11: Disclaimer: Sourced tourism = context only. Bookings/AOV/CAC/OpEx/take = ASSUMPTIONS. Pre-tax. Not investment advice.
A13: Companion: ../BUSINESS_PLAN_5YR.md | ../MARKETING_AND_SCALE.md

Sheet Assumptions
A1: GCCN 5-Year Financial Model — ASSUMPTIONS
A2: Yellow=INPUT. Tourism figures SOURCED for context only (NOT GCCN capture). Volumes/rates/costs=ASSUMPTIONS. Pre-tax USD. Stripe on PLATFORM FEE SLICE when U8=1.
A4: ID | B4: Parameter | C4: Conservative | D4: Base | E4: Upside | F4: Notes / Source
A5: SCENARIO_TOGGLE | B5: Active scenario for Annual_PnL Selected summary | C5: Base | D5: INPUT: Conservative | Base | Upside
A6: M1 | B6: Beach visitors 2024 (GSOB+FM) context | C6: 6490000 | D6: 6490000 | E6: 6490000 | F6: SOURCED Deravi/GSOBT ~6.49M — NOT capture
A7: M2 | B7: Beach visitors 2025 (GSOB+FM) context | C7: 7140000 | D7: 7140000 | E7: 7140000 | F7: SOURCED GSOBT/ATD ~7.14M — NOT capture
A8: M3 | B8: Lodging sales beaches 2025 $M context | C8: 923 | D8: 923 | E8: 923 | F8: SOURCED al.com/GSOBT ~$923M
A9: M4 | B9: Peak lodging tax share Apr-Sep | C9: 0.7 | D9: 0.7 | E9: 0.7 | F9: SOURCED ATD ~70% Apr-Sep
A10: U1 | B10: Blended AOV ($) | C10: 600 | D10: 750 | E10: 950 | F10: ASSUMPTION public price-band mix
A11: U2 | B11: Network take rate | C11: 0.1 | D11: 0.12 | E11: 0.14 | F11: ASSUMPTION 10-15% vs FH~6% / OTA 20-30% sourced
A12: U3 | B12: Owned/sister uplift on take (pts) | C12: 0.005 | D12: 0.015 | E12: 0.03 | F12: ASSUMPTION spear/owned mix
A13: U4 | B13: Effective take rate (U2+U3) | C13: =C11+C12 | D13: =D11+D12 | E13: =E11+E12 | F13: CALCULATED
A14: U5 | B14: Deposit fraction of AOV | C14: 0.3 | D14: 0.3 | E14: 0.35 | F14: ASSUMPTION
A15: U6 | B15: Stripe fee % | C15: 0.029 | D15: 0.029 | E15: 0.029 | F15: ASSUMPTION
A16: U7 | B16: Stripe fee fixed $/txn | C16: 0.3 | D16: 0.3 | E16: 0.3 | F16: ASSUMPTION
A17: U8 | B17: Stripe basis 1=fee slice 0=full GMV | C17: 1 | D17: 1 | E17: 1 | F17: ASSUMPTION recommended fee-slice
A18: U9 | B18: Partner referral % of GMV blended | C18: 0.01 | D18: 0.008 | E18: 0.005 | F18: ASSUMPTION
A19: U10 | B19: SMS/email $/booking | C19: 1.25 | D19: 1 | E19: 0.75 | F19: ASSUMPTION
A20: U11 | B20: Weather drag % of platform revenue | C20: 0.06 | D20: 0.04 | E20: 0.025 | F20: ASSUMPTION
A21: V1 | B21: Y1 completed bookings | C21: 450 | D21: 900 | E21: 1200 | F21: ASSUMPTION
A22: V2 | B22: Y2 bookings | C22: 669 | D22: 1395 | E22: 1897 | F22: ASSUMPTION
A23: V3 | B23: Y3 bookings | C23: 995 | D23: 2163 | E23: 3000 | F23: ASSUMPTION
A24: V4 | B24: Y4 bookings | C24: 1480 | D24: 3354 | E24: 4743 | F24: ASSUMPTION
A25: V5 | B25: Y5 bookings | C25: 2200 | D25: 5200 | E25: 7500 | F25: ASSUMPTION
... A39: CH3 | B39: OTA commission if used later | C39: 0.25 | D39: 0.25 | E39: 0.22 | F39: SOURCED ~20-30%
A42: LEGEND
B43: Yellow = INPUT
B44: Green = CALCULATED
A46: Partner keeps ~(1−take)×GMV (not GCCN OpEx). Platform COGS = Stripe(fee-slice)+referral+SMS+paid CAC+fixed OpEx.
A47: Sources in BUSINESS_PLAN_5YR.md (GSOBT/ATD, FareHarbor ~6%, OTA ~20-30%).

Sheet Annual_PnL
A1: GCCN Annual P&L — Y1–Y5 × Three Scenarios (pre-tax)
A2: GMV=bookings×AOV(with lift). Revenue=GMV×effective take×(1−weather drag). Stripe on fee slice if U8=1.
A4: Metric | B4: Y1 Cons | C4: Y1 Base | D4: Y1 Upsi | E4: Y2 Cons | F4: Y2 Base | G4: Y2 Upsi | H4: Y3 Cons | I4: Y3 Base | J4: Y3 Upsi | K4: Y4 Cons | L4: Y4 Base | M4: Y4 Upsi | N4: Y5 Cons | O4: Y5 Base | P4: Y5 Upsi
A5: Bookings | B5: =Assumptions!C21 | C5: =Assumptions!D21 | D5: =Assumptions!E21 | E5: =Assumptions!C22 | F5: =Assumptions!D22 | G5: =Assumptions!E22 | H5: =Assumptions!C23 | I5: =Assumptions!D23 | J5: =Assumptions!E23 | K5: =Assumptions!C24 | L5: =Assumptions!D24 | M5: =Assumptions!E24 | N5: =Assumptions!C25 | O5: =Assumptions!D25 | P5: =Assumptions!E25
A6: AOV ($) | B6: =(Assumptions!C10*(1+Assumptions!C26)^(1-1)) | C6: =(Assumptions!D10*(1+Assumptions!D26)^(1-1)) | D6: =(Assumptions!E10*(1+Assumptions!E26)^(1-1)) | E6: =(Assumptions!C10*(1+Assumptions!C26)^(2-1)) | F6: =(Assumptions!D10*(1+Assumptions!D26)^(2-1)) | G6: =(Assumptions!E10*(1+Assumptions!E26)^(2-1)) | H6: =(Assumptions!C10*(1+Assumptions!C26)^(3-1)) | I6: =(Assumptions!D10*(1+Assumptions!D26)^(3-1)) | J6: =(Assumptions!E10*(1+Assumptions!E26)^(3-1)) | K6: =(Assumptions!C10*(1+Assumptions!C26)^(4-1)) | L6: =(Assumptions!D10*(1+Assumptions!D26)^(4-1)) | M6: =(Assumptions!E10*(1+Assumptions!E26)^(4-1)) | N6: =(Assumptions!C10*(1+Assumptions!C26)^(5-1)) | O6: =(Assumptions!D10*(1+Assumptions!D26)^(5-1)) | P6: =(Assumptions!E10*(1+Assumptions!E26)^(5-1))
A7: GMV ($) | B7: =(Assumptions!C21*(Assumptions!C10*(1+Assumptions!C26)^(1-1))) | C7: =(Assumptions!D21*(Assumptions!D10*(1+Assumptions!D26)^(1-1))) | D7: =(Assumptions!E21*(Assumptions!E10*(1+Assumptions!E26)^(1-1))) | E7: =(Assumptions!C22*(Assumptions!C10*(1+Assumptions!C26)^(2-1))) | F7: =(Assumptions!D22*(Assumptions!D10*(1+Assumptions!D26)^(2-1))) | G7: =(Assumptions!E22*(Assumptions!E10*(1+Assumptions!E26)^(2-1))) | H7: =(Assumptions!C23*(Assumptions!C10*(1+Assumptions!C26)^(3-1))) | I7: =(Assumptions!D23*(Assumptions!D10*(1+Assumptions!D26)^(3-1))) | J7: =(Assumptions!E23*(Assumptions!E10*(1+Assumptions!E26)^(3-1))) | K7: =(Assumptions!C24*(Assumptions!C10*(1+Assumptions!C26)^(4-1))) | L7: =(Assumptions!D24*(Assumptions!D10*(1+Assumptions!D26)^(4-1))) | M7: =(Assumptions!E24*(Assumptions!E10*(1+Assumptions!E26)^(4-1))) | N7: =(Assumptions!C25*(Assumptions!C10*(1+Assumptions!C26)^(5-1))) | O7: =(Assumptions!D25*(Assumptions!D10*(1+Assumptions!D26)^(5-1))) | P7: =(Assumptions!E25*(Assumptions!E10*(1+Assumptions!E26)^(5-1)))
A8: Effective take rate | B8: =(Assumptions!C11+Assumptions!C12) | C8: =(Assumptions!D11+Assumptions!D12) | D8: =(Assumptions!E11+Assumptions!E12) | E8: =(Assumptions!C11+Assumptions!C12) | F8: =(Assumptions!D11+Assumptions!D12) | G8: =(Assumptions!E11+Assumptions!E12) | H8: =(Assumptions!C11+Assumptions!C12) | I8: =(Assumptions!D11+Assumptions!D12) | J8: =(Assumptions!E11+Assumptions!E12) | K8: =(Assumptions!C11+Assumptions!C12) | L8: =(Assumptions!D11+Assumptions!D12) | M8: =(Assumptions!E11+Assumptions!E12) | N8: =(Assumptions!C11+Assumptions!C12) | O8: =(Assumptions!D11+Assumptions!D12) | P8: =(Assumptions!E11+Assumptions!E12)
A9: Gross platform revenue ($) | B9: =((Assumptions!C21*(Assumptions!C10*(1+Assumptions!C26)^(1-1)))*(Assumptions!C11+Assumptions!C12)) | C9: =((Assumptions!D21*(Assumptions!D10*(1+Assumptions!D26)^(1-1)))*(Assumptions!D11+Assumptions!D12)) | D9: =((Assumptions!E21*(Assumptions!E10*(1+Assumptions!E26)^(1-1)))*(Assumptions!E11+Assumptions!E12)) | E9: =((Assumptions!C22*(Assumptions!C10*(1+Assumptions!C26)^(2-1)))*(Assumptions!C11+Assumptions!C12)) | F9: =((Assumptions!D22*(Assumptions!D10*(1+Assumptions!D26)^(2-1)))*(Assumptions!D11+Assumptions!D12)) | G9: =((Assumptions!E22*(Assumptions!E10*(1+Assumptions!E26)^(2-1)))*(Assumptions!E11+Assumptions!E12)) | H9: =((Assumptions!C23*(Assumptions!C10*(1+Assumptions!C26)^(3-1)))*(Assumptions!C11+Assumptions!C12)) | I9: =((Assumptions!D23*(Assumptions!D10*(1+Assumptions!D26)^(3-1)))*(Assumptions!D11+Assumptions!D12)) | J9: =((Assumptions!E23*(Assumptions!E10*(1+Assumptions!E26)^(3-1)))*(Assumptions!E11+Assumptions!E12)) | K9: =((Assumptions!C24*(Assumptions!C10*(1+Assumptions!C26)^(4-1)))*(Assumptions!C11+Assumptions!C12)) | L9: =((Assumptions!D24*(Assumptions!D10*(1+Assumptions!D26)^(4-1)))*(Assumptions!D11+Assumptions!D12)) | M9: =((Assumptions!E24*(Assumptions!E10*(1+Assumptions!E26)^(4-1)))*(Assumptions!E11+Assumptions!E12)) | N9: =((Assumptions!C25*(Assumptions!C10*(1+Assumptions!C26)^(5-1)))*(Assumptions!C11+Assumptions!C12)) | O9: =((Assumptions!D25*(Assumptions!D10*(1+Assumptions!D26)^(5-1)))*(Assumptions!D11+Assumptions!D12)) | P9: =((Assumptions!E25*(Assumptions!E10*(1+Assumptions!E26)^(5-1)))*(Assumptions!E11+Assumptions!E12))
A10: Revenue after weather drag ($) | B10: =(((Assumptions!C21*(Assumptions!C10*(1+Assumptions!C26)^(1-1)))*(Assumptions!C11+Assumptions!C12))*(1-Assumptions!C20)) | C10: =(((Assumptions!D21*(Assumptions!D10*(1+Assumptions!D26)^(1-1)))*(Assumptions!D11+Assumptions!D12))*(1-Assumptions!D20)) | D10: =(((Assumptions!E21*(Assumptions!E10*(1+Assumptions!E26)^(1-1)))*(Assumptions!E11+Assumptions!E12))*(1-Assumptions!E20)) | E10: =(((Assumptions!C22*(Assumptions!C10*(1+Assumptions!C26)^(2-1)))*(Assumptions!C11+Assumptions!C12))*(1-Assumptions!C20)) | F10: =(((Assumptions!D22*(Assumptions!D10*(1+Assumptions!D26)^(2-1)))*(Assumptions!D11+Assumptions!D12))*(1-Assumptions!D20)) | G10: =(((Assumptions!E22*(Assumptions!E10*(1+Assumptions!E26)^(2-1)))*(Assumptions!E11+Assumptions!E12))*(1-Assumptions!E20)) | H10: =(((Assumptions!C23*(Assumptions!C10*(1+Assumptions!C26)^(3-1)))*(Assumptions!C11+Assumptions!C12))*(1-Assumptions!C20)) | I10: =(((Assumptions!D23*(Assumptions!D10*(1+Assumptions!D26)^(3-1)))*(Assumptions!D11+Assumptions!D12))*(1-Assumptions!D20)) | J10: =(((Assumptions!E23*(Assumptions!E10*(1+Assumptions!E26)^(3-1)))*(Assumptions!E11+Assumptions!E12))*(1-Assumptions!E20)) | K10: =(((Assumptions!C24*(Assumptions!C10*(1+Assumptions!C26)^(4-1)))*(Assumptions!C11+Assumptions!C12))*(1-Assumptions!C20)) | L10: =(((Assumptions!D24*(Assumptions!D10*(1+Assumptions!D26)^(4-1)))*(Assumptions!D11+Assumptions!D12))*(1-Assumptions!D20)) | M10: =(((Assumptions!E24*(Assumptions!E10*(1+Assumptions!E26)^(4-1)))*(Assumptions!E11+Assumptions!E12))*(1-Assumptions!E20)) | N10: =(((Assumptions!C25*(Assumptions!C10*(1+Assumptions!C26)^(5-1)))*(Assumptions!C11+Assumptions!C12))*(1-Assumptions!C20)) | O10: =(((Assumptions!D25*(Assumptions!D10*(1+Assumptions!D26)^(5-1)))*(Assumptions!D11+Assumptions!D12))*(1-Assumptions!D20)) | P10: =(((Assumptions!E25*(Assumptions!E10*(1+Assumptions!E26)^(5-1)))*(Assumptions!E11+Assumptions!E12))*(1-Assumptions!E20))
A11: Stripe fees ($) | B11: =(IF(Assumptions!C17=1,(((Assumptions!C21*(Assumptions!C10*(1+Assumptions!C26)^(1-1)))*(Assumptions!C11+Assumptions!C12))*(1-Assumptions!C20))*Assumptions!C15+Assumptions!C21*Assumptions!C16,(Assumptions!C21*(Assumptions!C10*(1+Assumptions!C26)^(1-1)))*Assumptions!C15+Assumptions!C21*Assumptions!C16)) | C11: =(IF(Assumptions!D17=1,(((Assumptions!D21*(Assumptions!D10*(1+Assumptions!D26)^(1-1)))*(Assumptions!D11+Assumptions!D12))*(1-Assumptions!D20))*Assumptions!D15+Assumptions!D21*Assumptions!D16,(Assumptions!D21*(Assumptions!D10*(1+Assumptions!D26)^(1-1)))*Assumptions!D15+Assumptions!D21*Assumptions!D16)) | D11: =(IF(Assumptions!E17=1,(((Assumptions!E21*(Assumptions!E10*(1+Assumptions!E26)^(1-1)))*(Assumptions!E11+Assumptions!E12))*(1-Assumptions!E20))*Assumptions!E15+Assumptions!E21*Assumptions!E16,(Assumptions!E21*(Assumptions!E10*(1+Assumptions!E26)^(1-1)))*Assumptions!E15+Assumptions!E21*Assumptions!E16)) | E11: =(IF(Assumptions!C17=1,(((Assumptions!C22*(Assumptions!C10*(1+Assumptions!C26)^(2-1)))*(Assumptions!C11+Assumptions!C12))*(1-Assumptions!C20))*Assumptions!C15+Assumptions!C22*Assumptions!C16,(Assumptions!C22*(Assumptions!C10*(1+Assumptions!C26)^(2-1)))*Assumptions!C15+Assumptions!C22*Assumptions!C16)) | F11: =(IF(Assumptions!D17=1,(((Assumptions!D22*(Assumptions!D10*(1+Assumptions!D26)^(2-1)))*(Assumptions!D11+Assumptions!D12))*(1-Assumptions!D20))*Assumptions!D15+Assumptions!D22*Assumptions!D16,(Assumptions!D22*(Assumptions!D10*(1+Assumptions!D26)^(2-1)))*Assumptions!D15+Assumptions!D22*Assumptions!D16)) | G11: =(IF(Assumptions!E17=1,(((Assumptions!E22*(Assumptions!E10*(1+Assumptions!E26)^(2-1)))*(Assumptions!E11+Assumptions!E12))*(1-Assumptions!E20))*Assumptions!E15+Assumptions!E22*Assumptions!E16,(Assumptions!E22*(Assumptions!E10*(1+Assumptions!E26)^(2-1)))*Assumptions!E15+Assumptions!E22*Assumptions!E16)) | H11: =(IF(Assumptions!C17=1,(((Assumptions!C23*(Assumptions!C10*(1+Assumptions!C26)^(3-1)))*(Assumptions!C11+Assumptions!C12))*(1-Assumptions!C20))*Assumptions!C15+Assumptions!C23*Assumptions!C16,(Assumptions!C23*(Assumptions!C10*(1+Assumptions!C26)^(3-1)))*Assumptions!C15+Assumptions!C23*Assumptions!C16)) | I11: =(IF(Assumptions!D17=1,(((Assumptions!D23*(Assumptions!D10*(1+Assumptions!D26)^(3-1)))*(Assumptions!D11+Assumptions!D12))*(1-Assumptions!D20))*Assumptions!D15+Assumptions!D23*Assumptions!D16,(Assumptions!D23*(Assumptions!D10*(1+Assumptions!D26)^(3-1)))*Assumptions!D15+Assumptions!D23*Assumptions!D16)) | J11: =(IF(Assumptions!E17=1,(((Assumptions!E23*(Assumptions!E10*(1+Assumptions!E26)^(3-1)))*(Assumptions!E11+Assumptions!E12))*(1-Assumptions!E20))*Assumptions!E15+Assumptions!E23*Assumptions!E16,(Assumptions!E23*(Assumptions!E10*(1+Assumptions!E26)^(3-1)))*Assumptions!E15+Assumptions!E23*Assumptions!E16)) | K11: =(IF(Assumptions!C17=1,(((Assumptions!C24*(Assumptions!C10*(1+Assumptions!C26)^(4-1)))*(Assumptions!C11+Assumptions!C12))*(1-Assumptions!C20))*Assumptions!C15+Assumptions!C24*Assumptions!C16,(Assumptions!C24*(Assumptions!C10*(1+Assumptions!C26)^(4-1)))*Assumptions!C15+Assumptions!C24*Assumptions!C16)) | L11: =(IF(Assumptions!D17=1,(((Assumptions!D24*(Assumptions!D10*(1+Assumptions!D26)^(4-1)))*(Assumptions!D11+Assumptions!D12))*(1-Assumptions!D20))*Assumptions!D15+Assumptions!D24*Assumptions!D16,(Assumptions!D24*(Assumptions!D10*(1+Assumptions!D26)^(4-1)))*Assumptions!D15+Assumptions!D24*Assumptions!D16)) | M11: =(IF(Assumptions!E17=1,(((Assumptions!E24*(Assumptions!E10*(1+Assumptions!E26)^(4-1)))*(Assumptions!E11+Assumptions!E12))*(1-Assumptions!E20))*Assumptions!E15+Assumptions!E24*Assumptions!E16,(Assumptions!E24*(Assumptions!E10*(1+Assumptions!E26)^(4-1)))*Assumptions!E15+Assumptions!E24*Assumptions!E16)) | N11: =(IF(Assumptions!C17=1,(((Assumptions!C25*(Assumptions!C10*(1+Assumptions!C26)^(5-1)))*(Assumptions!C11+Assumptions!C12))*(1-Assumptions!C20))*Assumptions!C15+Assumptions!C25*Assumptions!C16,(Assumptions!C25*(Assumptions!C10*(1+Assumptions!C26)^(5-1)))*Assumptions!C15+Assumptions!C25*Assumptions!C16)) | O11: =(IF(Assumptions!D17=1,(((Assumptions!D25*(Assumptions!D10*(1+Assumptions!D26)^(5-1)))*(Assumptions!D11+Assumptions!D12))*(1-Assumptions!D20))*Assumptions!D15+Assumptions!D25*Assumptions!D16,(Assumptions!D25*(Assumptions!D10*(1+Assumptions!D26)^(5-1)))*Assumptions!D15+Assumptions!D25*Assumptions!D16)) | P11: =(IF(Assumptions!E17=1,(((Assumptions!E25*(Assumptions!E10*(1+Assumptions!E26)^(5-1)))*(Assumptions!E11+Assumptions!E12))*(1-Assumptions!E20))*Assumptions!E15+Assumptions!E25*Assumptions!E16,(Assumptions!E25*(Assumptions!E10*(1+Assumptions!E26)^(5-1)))*Assumptions!E15+Assumptions!E25*Assumptions!E16))
A12: Partner referral credits ($) | B12: =((Assumptions!C21*(Assumptions!C10*(1+Assumptions!C26)^(1-1)))*Assumptions!C18) | C12: =((Assumptions!D21*(Assumptions!D10*(1+Assumptions!D26)^(1-1)))*Assumptions!D18) | D12: =((Assumptions!E21*(Assumptions!E10*(1+Assumptions!E26)^(1-1)))*Assumptions!E18) | E12: =((Assumptions!C22*(Assumptions!C10*(1+Assumptions!C26)^(2-1)))*Assumptions!C18) | F12: =((Assumptions!D22*(Assumptions!D10*(1+Assumptions!D26)^(2-1)))*Assumptions!D18) | G12: =((Assumptions!E22*(Assumptions!E10*(1+Assumptions!E26)^(2-1)))*Assumptions!E18) | H12: =((Assumptions!C23*(Assumptions!C10*(1+Assumptions!C26)^(3-1)))*Assumptions!C18) | I12: =((Assumptions!D23*(Assumptions!D10*(1+Assumptions!D26)^(3-1)))*Assumptions!D18) | J12: =((Assumptions!E23*(Assumptions!E10*(1+Assumptions!E26)^(3-1)))*Assumptions!E18) | K12: =((Assumptions!C24*(Assumptions!C10*(1+Assumptions!C26)^(4-1)))*Assumptions!C18) | L12: =((Assumptions!D24*(Assumptions!D10*(1+Assumptions!D26)^(4-1)))*Assumptions!D18) | M12: =((Assumptions!E24*(Assumptions!E10*(1+Assumptions!E26)^(4-1)))*Assumptions!E18) | N12: =((Assumptions!C25*(Assumptions!C10*(1+Assumptions!C26)^(5-1)))*Assumptions!C18) | O12: =((Assumptions!D25*(Assumptions!D10*(1+Assumptions!D26)^(5-1)))*Assumptions!D18) | P12: =((Assumptions!E25*(Assumptions!E10*(1+Assumptions!E26)^(5-1)))*Assumptions!E18)
A13: SMS/email variable ($) | B13: =(Assumptions!C21*Assumptions!C19) | C13: =(Assumptions!D21*Assumptions!D19) | D13: =(Assumptions!E21*Assumptions!E19) | E13: =(Assumptions!C22*Assumptions!C19) | F13: =(Assumptions!D22*Assumptions!D19) | G13: =(Assumptions!E22*Assumptions!E19) | H13: =(Assumptions!C23*Assumptions!C19) | I13: =(Assumptions!D23*Assumptions!D19) | J13: =(Assumptions!E23*Assumptions!E19) | K13: =(Assumptions!C24*Assumptions!C19) | L13: =(Assumptions!D24*Assumptions!D19) | M13: =(Assumptions!E24*Assumptions!E19) | N13: =(Assumptions!C25*Assumptions!C19) | O13: =(Assumptions!D25*Assumptions!D19) | P13: =(Assumptions!E25*Assumptions!E19)
A14: Variable COGS subtotal ($) | B14: =((IF(Assumptions!C17=1,(((Assumptions!C21*(Assumptions!C10*(1+Assumptions!C26)^(1-1)))*(Assumptions!C11+Assumptions!C12))*(1-Assumptions!C20))*Assumptions!C15+Assumptions!C21*Assumptions!C16,(Assumptions!C21*(Assumptions!C10*(1+Assumptions!C26)^(1-1)))*Assumptions!C15+Assumptions!C21*Assumptions!C16))+((Assumptions!C21*(Assumptions!C10*(1+Assumptions!C26)^(1-1)))*Assumptions!C18)+(Assumptions!C21*Assumptions!C19)) | C14: =((IF(Assumptions!D17=1,(((Assumptions!D21*(Assumptions!D10*(1+Assumptions!D26)^(1-1)))*(Assumptions!D11+Assumptions!D12))*(1-Assumptions!D20))*Assumptions!D15+Assumptions!D21*Assumptions!D16,(Assumptions!D21*(Assumptions!D10*(1+Assumptions!D26)^(1-1)))*Assumptions!D15+Assumptions!D21*Assumptions!D16))+((Assumptions!D21*(Assumptions!D10*(1+Assumptions!D26)^(1-1)))*Assumptions!D18)+(Assumptions!D21*Assumptions!D19)) | D14: =((IF(Assumptions!E17=1,(((Assumptions!E21*(Assumptions!E10*(1+Assumptions!E26)^(1-1)))*(Assumptions!E11+Assumptions!E12))*(1-Assumptions!E20))*Assumptions!E15+Assumptions!E21*Assumptions!E16,(Assumptions!E21*(Assumptions!E10*(1+Assumptions!E26)^(1-1)))*Assumptions!E15+Assumptions!E21*Assumptions!E16))+((Assumptions!E21*(Assumptions!E10*(1+Assumptions!E26)^(1-1)))*Assumptions!E18)+(Assumptions!E21*Assumptions!E19)) | E14: =((IF(Assumptions!C17=1,(((Assumptions!C22*(Assumptions!C10*(1+Assumptions!C26)^(2-1)))*(Assumptions!C11+Assumptions!C12))*(1-Assumptions!C20))*Assumptions!C15+Assumptions!C22*Assumptions!C16,(Assumptions!C22*(Assumptions!C10*(1+Assumptions!C26)^(2-1)))*Assumptions!C15+Assumptions!C22*Assumptions!C16))+((Assumptions!C22*(Assumptions!C10*(1+Assumptions!C26)^(2-1)))*Assumptions!C18)+(Assumptions!C22*Assumptions!C19)) | F14: =((IF(Assumptions!D17=1,(((Assumptions!D22*(Assumptions!D10*(1+Assumptions!D26)^(2-1)))*(Assumptions!D11+Assumptions!D12))*(1-Assumptions!D20))*Assumptions!D15+Assumptions!D22*Assumptions!D16,(Assumptions!D22*(Assumptions!D10*(1+Assumptions!D26)^(2-1)))*Assumptions!D15+Assumptions!D22*Assumptions!D16))+((Assumptions!D22*(Assumptions!D10*(1+Assumptions!D26)^(2-1)))*Assumptions!D18)+(Assumptions!D22*Assumptions!D19)) | G14: =((IF(Assumptions!E17=1,(((Assumptions!E22*(Assumptions!E10*(1+Assumptions!E26)^(2-1)))*(Assumptions!E11+Assumptions!E12))*(1-Assumptions!E20))*Assumptions!E15+Assumptions!E22*Assumptions!E16,(Assumptions!E22*(Assumptions!E10*(1+Assumptions!E26)^(2-1)))*Assumptions!E15+Assumptions!E22*Assumptions!E16))+((Assumptions!E22*(Assumptions!E10*(1+Assumptions!E26)^(2-1)))*Assumptions!E18)+(Assumptions!E22*Assumptions!E19)) | H14: =((IF(Assumptions!C17=1,(((Assumptions!C23*(Assumptions!C10*(1+Assumptions!C26)^(3-1)))*(Assumptions!C11+Assumptions!C12))*(1-Assumptions!C20))*Assumptions!C15+Assumptions!C23*Assumptions!C16,(Assumptions!C23*(Assumptions!C10*(1+Assumptions!C26)^(3-1)))*Assumptions!C15+Assumptions!C23*Assumptions!C16))+((Assumptions!C23*(Assumptions!C10*(1+Assumptions!C26)^(3-1)))*Assumptions!C18)+(Assumptions!C23*Assumptions!C19)) | I14: =((IF(Assumptions!D17=1,(((Assumptions!D23*(Assumptions!D10*(1+Assumptions!D26)^(3-1)))*(Assumptions!D11+Assumptions!D12))*(1-Assumptions!D20))*Assumptions!D15+Assumptions!D23*Assumptions!D16,(Assumptions!D23*(Assumptions!D10*(1+Assumptions!D26)^(3-1)))*Assumptions!D15+Assumptions!D23*Assumptions!D16))+((Assumptions!D23*(Assumptions!D10*(1+Assumptions!D26)^(3-1)))*Assumptions!D18)+(Assumptions!D23*Assumptions!D19)) | J14: =((IF(Assumptions!E17=1,(((Assumptions!E23*(Assumptions!E10*(1+Assumptions!E26)^(3-1)))*(Assumptions!E11+Assumptions!E12))*(1-Assumptions!E20))*Assumptions!E15+Assumptions!E23*Assumptions!E16,(Assumptions!E23*(Assumptions!E10*(1+Assumptions!E26)^(3-1)))*Assumptions!E15+Assumptions!E23*Assumptions!E16))+((Assumptions!E23*(Assumptions!E10*(1+Assumptions!E26)^(3-1)))*Assumptions!E18)+(Assumptions!E23*Assumptions!E19)) | K14: =((IF(Assumptions!C17=1,(((Assumptions!C24*(Assumptions!C10*(1+Assumptions!C26)^(4-1)))*(Assumptions!C11+Assumptions!C12))*(1-Assumptions!C20))*Assumptions!C15+Assumptions!C24*Assumptions!C16,(Assumptions!C24*(Assumptions!C10*(1+Assumptions!C26)^(4-1)))*Assumptions!C15+Assumptions!C24*Assumptions!C16))+((Assumptions!C24*(Assumptions!C10*(1+Assumptions!C26)^(4-1)))*Assumptions!C18)+(Assumptions!C24*Assumptions!C19)) | L14: =((IF(Assumptions!D17=1,(((Assumptions!D24*(Assumptions!D10*(1+Assumptions!D26)^(4-1)))*(Assumptions!D11+Assumptions!D12))*(1-Assumptions!D20))*Assumptions!D15+Assumptions!D24*Assumptions!D16,(Assumptions!D24*(Assumptions!D10*(1+Assumptions!D26)^(4-1)))*Assumptions!D15+Assumptions!D24*Assumptions!D16))+((Assumptions!D24*(Assumptions!D10*(1+Assumptions!D26)^(4-1)))*Assumptions!D18)+(Assumptions!D24*Assumptions!D19)) | M14: =((IF(Assumptions!E17=1,(((Assumptions!E24*(Assumptions!E10*(1+Assumptions!E26)^(4-1)))*(Assumptions!E11+Assumptions!E12))*(1-Assumptions!E20))*Assumptions!E15+Assumptions!E24*Assumptions!E16,(Assumptions!E24*(Assumptions!E10*(1+Assumptions!E26)^(4-1)))*Assumptions!E15+Assumptions!E24*Assumptions!E16))+((Assumptions!E24*(Assumptions!E10*(1+Assumptions!E26)^(4-1)))*Assumptions!E18)+(Assumptions!E24*Assumptions!E19)) | N14: =((IF(Assumptions!C17=1,(((Assumptions!C25*(Assumptions!C10*(1+Assumptions!C26)^(5-1)))*(Assumptions!C11+Assumptions!C12))*(1-Assumptions!C20))*Assumptions!C15+Assumptions!C25*Assumptions!C16,(Assumptions!C25*(Assumptions!C10*(1+Assumptions!C26)^(5-1)))*Assumptions!C15+Assumptions!C25*Assumptions!C16))+((Assumptions!C25*(Assumptions!C10*(1+Assumptions!C26)^(5-1)))*Assumptions!C18)+(Assumptions!C25*Assumptions!C19)) | O14: =((IF(Assumptions!D17=1,(((Assumptions!D25*(Assumptions!D10*(1+Assumptions!D26)^(5-1)))*(Assumptions!D11+Assumptions!D12))*(1-Assumptions!D20))*Assumptions!D15+Assumptions!D25*Assumptions!D16,(Assumptions!D25*(Assumptions!D10*(1+Assumptions!D26)^(5-1)))*Assumptions!D15+Assumptions!D25*Assumptions!D16))+((Assumptions!D25*(Assumptions!D10*(1+Assumptions!D26)^(5-1)))*Assumptions!D18)+(Assumptions!D25*Assumptions!D19)) | P14: =((IF(Assumptions!E17=1,(((Assumptions!E25*(Assumptions!E10*(1+Assumptions!E26)^(5-1)))*(Assumptions!E11+Assumptions!E12))*(1-Assumptions!E20))*Assumptions!E15+Assumptions!E25*Assumptions!E16,(Assumptions!E25*(Assumptions!E10*(1+Assumptions!E26)^(5-1)))*Assumptions!E15+Assumptions!E25*Assumptions!E16))+((Assumptions!E25*(Assumptions!E10*(1+Assumptions!E26)^(5-1)))*Assumptions!E18)+(Assumptions!E25*Assumptions!E19))
A15: Contribution after var COGS ($) | B15: =((((Assumptions!C21*(Assumptions!C10*(1+Assumptions!C26)^(1-1)))*(Assumptions!C11+Assumptions!C12))*(1-Assumptions!C20))-((IF(Assumptions!C17=1,(((Assumptions!C21*(Assumptions!C10*(1+Assumptions!C26)^(1-1)))*(Assumptions!C11+Assumptions!C12))*(1-Assumptions!C20))*Assumptions!C15+Assumptions!C21*Assumptions!C16,(Assumptions!C21*(Assumptions!C10*(1+Assumptions!C26)^(1-1)))*Assumptions!C15+Assumptions!C21*Assumptions!C16))+((Assumptions!C21*(Assumptions!C10*(1+Assumptions!C26)^(1-1)))*Assumptions!C18)+(Assumptions!C21*Assumptions!C19))) | C15: =((((Assumptions!D21*(Assumptions!D10*(1+Assumptions!D26)^(1-1)))*(Assumptions!D11+Assumptions!D12))*(1-Assumptions!D20))-((IF(Assumptions!D17=1,(((Assumptions!D21*(Assumptions!D10*(1+Assumptions!D26)^(1-1)))*(Assumptions!D11+Assumptions!D12))*(1-Assumptions!D20))*Assumptions!D15+Assumptions!D21*Assumptions!D16,(Assumptions!D21*(Assumptions!D10*(1+Assumptions!D26)^(1-1)))*Assumptions!D15+Assumptions!D21*Assumptions!D16))+((Assumptions!D21*(Assumptions!D10*(1+Assumptions!D26)^(1-1)))*Assumptions!D18)+(Assumptions!D21*Assumptions!D19))) | D15: =((((Assumptions!E21*(Assumptions!E10*(1+Assumptions!E26)^(1-1)))*(Assumptions!E11+Assumptions!E12))*(1-Assumptions!E20))-((IF(Assumptions!E17=1,(((Assumptions!E21*(Assumptions!E10*(1+Assumptions!E26)^(1-1)))*(Assumptions!E11+Assumptions!E12))*(1-Assumptions!E20))*Assumptions!E15+Assumptions!E21*Assumptions!E16,(Assumptions!E21*(Assumptions!E10*(1+Assumptions!E26)^(1-1)))*Assumptions!E15+Assumptions!E21*Assumptions!E16))+((Assumptions!E21*(Assumptions!E10*(1+Assumptions!E26)^(1-1)))*Assumptions!E18)+(Assumptions!E21*Assumptions!E19))) | E15: =((((Assumptions!C22*(Assumptions!C10*(1+Assumptions!C26)^(2-1)))*(Assumptions!C11+Assumptions!C12))*(1-Assumptions!C20))-((IF(Assumptions!C17=1,(((Assumptions!C22*(Assumptions!C10*(1+Assumptions!C26)^(2-1)))*(Assumptions!C11+Assumptions!C12))*(1-Assumptions!C20))*Assumptions!C15+Assumptions!C22*Assumptions!C16,(Assumptions!C22*(Assumptions!C10*(1+Assumptions!C26)^(2-1)))*Assumptions!C15+Assumptions!C22*Assumptions!C16))+((Assumptions!C22*(Assumptions!C10*(1+Assumptions!C26)^(2-1)))*Assumptions!C18)+(Assumptions!C22*Assumptions!C19))) | F15: =((((Assumptions!D22*(Assumptions!D10*(1+Assumptions!D26)^(2-1)))*(Assumptions!D11+Assumptions!D12))*(1-Assumptions!D20))-((IF(Assumptions!D17=1,(((Assumptions!D22*(Assumptions!D10*(1+Assumptions!D26)^(2-1)))*(Assumptions!D11+Assumptions!D12))*(1-Assumptions!D20))*Assumptions!D15+Assumptions!D22*Assumptions!D16,(Assumptions!D22*(Assumptions!D10*(1+Assumptions!D26)^(2-1)))*Assumptions!D15+Assumptions!D22*Assumptions!D16))+((Assumptions!D22*(Assumptions!D10*(1+Assumptions!D26)^(2-1)))*Assumptions!D18)+(Assumptions!D22*Assumptions!D19))) | G15: =((((Assumptions!E22*(Assumptions!E10*(1+Assumptions!E26)^(2-1)))*(Assumptions!E11+Assumptions!E12))*(1-Assumptions!E20))-((IF(Assumptions!E17=1,(((Assumptions!E22*(Assumptions!E10*(1+Assumptions!E26)^(2-1)))*(Assumptions!E11+Assumptions!E12))*(1-Assumptions!E20))*Assumptions!E15+Assumptions!E22*Assumptions!E16,(Assumptions!E22*(Assumptions!E10*(1+Assumptions!E26)^(2-1)))*Assumptions!E15+Assumptions!E22*Assumptions!E16))+((Assumptions!E22*(Assumptions!E10*(1+Assumptions!E26)^(2-1)))*Assumptions!E18)+(Assumptions!E22*Assumptions!E19))) | H15: =((((Assumptions!C23*(Assumptions!C10*(1+Assumptions!C26)^(3-1)))*(Assumptions!C11+Assumptions!C12))*(1-Assumptions!C20))-((IF(Assumptions!C17=1,(((Assumptions!C23*(Assumptions!C10*(1+Assumptions!C26)^(3-1)))*(Assumptions!C11+Assumptions!C12))*(1-Assumptions!C20))*Assumptions!C15+Assumptions!C23*Assumptions!C16,(Assumptions!C23*(Assumptions!C10*(1+Assumptions!C26)^(3-1)))*Assumptions!C15+Assumptions!C23*Assumptions!C16))+((Assumptions!C23*(Assumptions!C10*(1+Assumptions!C26)^(3-1)))*Assumptions!C18)+(Assumptions!C23*Assumptions!C19))) | I15: =((((Assumptions!D23*(Assumptions!D10*(1+Assumptions!D26)^(3-1)))*(Assumptions!D11+Assumptions!D12))*(1-Assumptions!D20))-((IF(Assumptions!D17=1,(((Assumptions!D23*(Assumptions!D10*(1+Assumptions!D26)^(3-1)))*(Assumptions!D11+Assumptions!D12))*(1-Assumptions!D20))*Assumptions!D15+Assumptions!D23*Assumptions!D16,(Assumptions!D23*(Assumptions!D10*(1+Assumptions!D26)^(3-1)))*Assumptions!D15+Assumptions!D23*Assumptions!D16))+((Assumptions!D23*(Assumptions!D10*(1+Assumptions!D26)^(3-1)))*Assumptions!D18)+(Assumptions!D23*Assumptions!D19))) | J15: =((((Assumptions!E23*(Assumptions!E10*(1+Assumptions!E26)^(3-1)))*(Assumptions!E11+Assumptions!E12))*(1-Assumptions!E20))-((IF(Assumptions!E17=1,(((Assumptions!E23*(Assumptions!E10*(1+Assumptions!E26)^(3-1)))*(Assumptions!E11+Assumptions!E12))*(1-Assumptions!E20))*Assumptions!E15+Assumptions!E23*Assumptions!E16,(Assumptions!E23*(Assumptions!E10*(1+Assumptions!E26)^(3-1)))*Assumptions!E15+Assumptions!E23*Assumptions!E16))+((Assumptions!E23*(Assumptions!E10*(1+Assumptions!E26)^(3-1)))*Assumptions!E18)+(Assumptions!E23*Assumptions!E19))) | K15: =((((Assumptions!C24*(Assumptions!C10*(1+Assumptions!C26)^(4-1)))*(Assumptions!C11+Assumptions!C12))*(1-Assumptions!C20))-((IF(Assumptions!C17=1,(((Assumptions!C24*(Assumptions!C10*(1+Assumptions!C26)^(4-1)))*(Assumptions!C11+Assumptions!C12))*(1-Assumptions!C20))*Assumptions!C15+Assumptions!C24*Assumptions!C16,(Assumptions!C24*(Assumptions!C10*(1+Assumptions!C26)^(4-1)))*Assumptions!C15+Assumptions!C24*Assumptions!C16))+((Assumptions!C24*(Assumptions!C10*(1+Assumptions!C26)^(4-1)))*Assumptions!C18)+(Assumptions!C24*Assumptions!C19))) | L15: =((((Assumptions!D24*(Assumptions!D10*(1+Assumptions!D26)^(4-1)))*(Assumptions!D11+Assumptions!D12))*(1-Assumptions!D20))-((IF(Assumptions!D17=1,(((Assumptions!D24*(Assumptions!D10*(1+Assumptions!D26)^(4-1)))*(Assumptions!D11+Assumptions!D12))*(1-Assumptions!D20))*Assumptions!D15+Assumptions!D24*Assumptions!D16,(Assumptions!D24*(Assumptions!D10*(1+Assumptions!D26)^(4-1)))*Assumptions!D15+Assumptions!D24*Assumptions!D16))+((Assumptions!D24*(Assumptions!D10*(1+Assumptions!D26)^(4-1)))*Assumptions!D18)+(Assumptions!D24*Assumptions!D19))) | M15: =((((Assumptions!E24*(Assumptions!E10*(1+Assumptions!E26)^(4-1)))*(Assumptions!E11+Assumptions!E12))*(1-Assumptions!E20))-((IF(Assumptions!E17=1,(((Assumptions!E24*(Assumptions!E10*(1+Assumptions!E26)^(4-1)))*(Assumptions!E11+Assumptions!E12))*(1-Assumptions!E20))*Assumptions!E15+Assumptions!E24*Assumptions!E16,(Assumptions!E24*(Assumptions!E10*(1+Assumptions!E26)^(4-1)))*Assumptions!E15+Assumptions!E24*Assumptions!E16))+((Assumptions!E24*(Assumptions!E10*(1+Assumptions!E26)^(4-1)))*Assumptions!E18)+(Assumptions!E24*Assumptions!E19))) | N15: =((((Assumptions!C25*(Assumptions!C10*(1+Assumptions!C26)^(5-1)))*(Assumptions!C11+Assumptions!C12))*(1-Assumptions!C20))-((IF(Assumptions!C17=1,(((Assumptions!C25*(Assumptions!C10*(1+Assumptions!C26)^(5-1)))*(Assumptions!C11+Assumptions!C12))*(1-Assumptions!C20))*Assumptions!C15+Assumptions!C25*Assumptions!C16,(Assumptions!C25*(Assumptions!C10*(1+Assumptions!C26)^(5-1)))*Assumptions!C15+Assumptions!C25*Assumptions!C16))+((Assumptions!C25*(Assumptions!C10*(1+Assumptions!C26)^(5-1)))*Assumptions!C18)+(Assumptions!C25*Assumptions!C19))) | O15: =((((Assumptions!D25*(Assumptions!D10*(1+Assumptions!D26)^(5-1)))*(Assumptions!D11+Assumptions!D12))*(1-Assumptions!D20))-((IF(Assumptions!D17=1,(((Assumptions!D25*(Assumptions!D10*(1+Assumptions!D26)^(5-1)))*(Assumptions!D11+Assumptions!D12))*(1-Assumptions!D20))*Assumptions!D15+Assumptions!D25*Assumptions!D16,(Assumptions!D25*(Assumptions!D10*(1+Assumptions!D26)^(5-1)))*Assumptions!D15+Assumptions!D25*Assumptions!D16))+((Assumptions!D25*(Assumptions!D10*(1+Assumptions!D26)^(5-1)))*Assumptions!D18)+(Assumptions!D25*Assumptions!D19))) | P15: =((((Assumptions!E25*(Assumptions!E10*(1+Assumptions!E26)^(5-1)))*(Assumptions!E11+Assumptions!E12))*(1-Assumptions!E20))-((IF(Assumptions!E17=1,(((Assumptions!E25*(Assumptions!E10*(1+Assumptions!E26)^(5-1)))*(Assumptions!E11+Assumptions!E12))*(1-Assumptions!E20))*Assumptions!E15+Assumptions!E25*Assumptions!E16,(Assumptions!E25*(Assumptions!E10*(1+Assumptions!E26)^(5-1)))*Assumptions!E15+Assumptions!E25*Assumptions!E16))+((Assumptions!E25*(Assumptions!E10*(1+Assumptions!E26)^(5-1)))*Assumptions!E18)+(Assumptions!E25*Assumptions!E19)))
A16: Paid acquisition spend ($) | B16: =(Assumptions!C21*(Assumptions!C28+(Assumptions!C29-Assumptions!C28)*(1-1)/4)*Assumptions!C27) | C16: =(Assumptions!D21*(Assumptions!D28+(Assumptions!D29-Assumptions!D28)*(1-1)/4)*Assumptions!D27) | D16: =(Assumptions!E21*(Assumptions!E28+(Assumptions!E29-Assumptions!E28)*(1-1)/4)*Assumptions!E27) | E16: =(Assumptions!C22*(Assumptions!C28+(Assumptions!C29-Assumptions!C28)*(2-1)/4)*Assumptions!C27) | F16: =(Assumptions!D22*(Assumptions!D28+(Assumptions!D29-Assumptions!D28)*(2-1)/4)*Assumptions!D27) | G16: =(Assumptions!E22*(Assumptions!E28+(Assumptions!E29-Assumptions!E28)*(2-1)/4)*Assumptions!E27) | H16: =(Assumptions!C23*(Assumptions!C28+(Assumptions!C29-Assumptions!C28)*(3-1)/4)*Assumptions!C27) | I16: =(Assumptions!D23*(Assumptions!D28+(Assumptions!D29-Assumptions!D28)*(3-1)/4)*Assumptions!D27) | J16: =(Assumptions!E23*(Assumptions!E28+(Assumptions!E29-Assumptions!E28)*(3-1)/4)*Assumptions!E27) | K16: =(Assumptions!C24*(Assumptions!C28+(Assumptions!C29-Assumptions!C28)*(4-1)/4)*Assumptions!C27) | L16: =(Assumptions!D24*(Assumptions!D28+(Assumptions!D29-Assumptions!D28)*(4-1)/4)*Assumptions!D27) | M16: =(Assumptions!E24*(Assumptions!E28+(Assumptions!E29-Assumptions!E28)*(4-1)/4)*Assumptions!E27) | N16: =(Assumptions!C25*(Assumptions!C28+(Assumptions!C29-Assumptions!C28)*(5-1)/4)*Assumptions!C27) | O16: =(Assumptions!D25*(Assumptions!D28+(Assumptions!D29-Assumptions!D28)*(5-1)/4)*Assumptions!D27) | P16: =(Assumptions!E25*(Assumptions!E28+(Assumptions!E29-Assumptions!E28)*(5-1)/4)*Assumptions!E27)
A17: Fixed + brand OpEx ($) | B17: =((Assumptions!C31+Assumptions!C32+Assumptions!C33+Assumptions!C34)*(1+Assumptions!C35)^(1-1)+Assumptions!C30*(1+Assumptions!C36)^(1-1)) | C17: =((Assumptions!D31+Assumptions!D32+Assumptions!D33+Assumptions!D34)*(1+Assumptions!D35)^(1-1)+Assumptions!D30*(1+Assumptions!D36)^(1-1)) | D17: =((Assumptions!E31+Assumptions!E32+Assumptions!E33+Assumptions!E34)*(1+Assumptions!E35)^(1-1)+Assumptions!E30*(1+Assumptions!E36)^(1-1)) | E17: =((Assumptions!C31+Assumptions!C32+Assumptions!C33+Assumptions!C34)*(1+Assumptions!C35)^(2-1)+Assumptions!C30*(1+Assumptions!C36)^(2-1)) | F17: =((Assumptions!D31+Assumptions!D32+Assumptions!D33+Assumptions!D34)*(1+Assumptions!D35)^(2-1)+Assumptions!D30*(1+Assumptions!D36)^(2-1)) | G17: =((Assumptions!E31+Assumptions!E32+Assumptions!E33+Assumptions!E34)*(1+Assumptions!E35)^(2-1)+Assumptions!E30*(1+Assumptions!E36)^(2-1)) | H17: =((Assumptions!C31+Assumptions!C32+Assumptions!C33+Assumptions!C34)*(1+Assumptions!C35)^(3-1)+Assumptions!C30*(1+Assumptions!C36)^(3-1)) | I17: =((Assumptions!D31+Assumptions!D32+Assumptions!D33+Assumptions!D34)*(1+Assumptions!D35)^(3-1)+Assumptions!D30*(1+Assumptions!D36)^(3-1)) | J17: =((Assumptions!E31+Assumptions!E32+Assumptions!E33+Assumptions!E34)*(1+Assumptions!E35)^(3-1)+Assumptions!E30*(1+Assumptions!E36)^(3-1)) | K17: =((Assumptions!C31+Assumptions!C32+Assumptions!C33+Assumptions!C34)*(1+Assumptions!C35)^(4-1)+Assumptions!C30*(1+Assumptions!C36)^(4-1)) | L17: =((Assumptions!D31+Assumptions!D32+Assumptions!D33+Assumptions!D34)*(1+Assumptions!D35)^(4-1)+Assumptions!D30*(1+Assumptions!D36)^(4-1)) | M17: =((Assumptions!E31+Assumptions!E32+Assumptions!E33+Assumptions!E34)*(1+Assumptions!E35)^(4-1)+Assumptions!E30*(1+Assumptions!E36)^(4-1)) | N17: =((Assumptions!C31+Assumptions!C32+Assumptions!C33+Assumptions!C34)*(1+Assumptions!C35)^(5-1)+Assumptions!C30*(1+Assumptions!C36)^(5-1)) | O17: =((Assumptions!D31+Assumptions!D32+Assumptions!D33+Assumptions!D34)*(1+Assumptions!D35)^(5-1)+Assumptions!D30*(1+Assumptions!D36)^(5-1)) | P17: =((Assumptions!E31+Assumptions!E32+Assumptions!E33+Assumptions!E34)*(1+Assumptions!E35)^(5-1)+Assumptions!E30*(1+Assumptions!E36)^(5-1))
A18: Total costs excl. operator payout ($) | B18: =((IF(Assumptions!C17=1,(((Assumptions!C21*(Assumptions!C10*(1+Assumptions!C26)^(1-1)))*(Assumptions!C11+Assumptions!C12))*(1-Assumptions!C20))*Assumptions!C15+Assumptions!C21*Assumptions!C16,(Assumptions!C21*(Assumptions!C10*(1+Assumptions!C26)^(1-1)))*Assumptions!C15+Assumptions!C21*Assumptions!C16))+((Assumptions!C21*(Assumptions!C10*(1+Assumptions!C26)^(1-1)))*Assumptions!C18)+(Assumptions!C21*Assumptions!C19))+(Assumptions!C21*(Assumptions!C28+(Assumptions!C29-Assumptions!C28)*(1-1)/4)*Assumptions!C27)+((Assumptions!C31+Assumptions!C32+Assumptions!C33+Assumptions!C34)*(1+Assumptions!C35)^(1-1)+Assumptions!C30*(1+Assumptions!C36)^(1-1)) | C18: =((IF(Assumptions!D17=1,(((Assumptions!D21*(Assumptions!D10*(1+Assumptions!D26)^(1-1)))*(Assumptions!D11+Assumptions!D12))*(1-Assumptions!D20))*Assumptions!D15+Assumptions!D21*Assumptions!D16,(Assumptions!D21*(Assumptions!D10*(1+Assumptions!D26)^(1-1)))*Assumptions!D15+Assumptions!D21*Assumptions!D16))+((Assumptions!D21*(Assumptions!D10*(1+Assumptions!D26)^(1-1)))*Assumptions!D18)+(Assumptions!D21*Assumptions!D19))+(Assumptions!D21*(Assumptions!D28+(Assumptions!D29-Assumptions!D28)*(1-1)/4)*Assumptions!D27)+((Assumptions!D31+Assumptions!D32+Assumptions!D33+Assumptions!D34)*(1+Assumptions!D35)^(1-1)+Assumptions!D30*(1+Assumptions!D36)^(1-1)) | D18: =((IF(Assumptions!E17=1,(((Assumptions!E21*(Assumptions!E10*(1+Assumptions!E26)^(1-1)))*(Assumptions!E11+Assumptions!E12))*(1-Assumptions!E20))*Assumptions!E15+Assumptions!E21*Assumptions!E16,(Assumptions!E21*(Assumptions!E10*(1+Assumptions!E26)^(1-1)))*Assumptions!E15+Assumptions!E21*Assumptions!E16))+((Assumptions!E21*(Assumptions!E10*(1+Assumptions!E26)^(1-1)))*Assumptions!E18)+(Assumptions!E21*Assumptions!E19))+(Assumptions!E21*(Assumptions!E28+(Assumptions!E29-Assumptions!E28)*(1-1)/4)*Assumptions!E27)+((Assumptions!E31+Assumptions!E32+Assumptions!E33+Assumptions!E34)*(1+Assumptions!E35)^(1-1)+Assumptions!E30*(1+Assumptions!E36)^(1-1)) | E18: =((IF(Assumptions!C17=1,(((Assumptions!C22*(Assumptions!C10*(1+Assumptions!C26)^(2-1)))*(Assumptions!C11+Assumptions!C12))*(1-Assumptions!C20))*Assumptions!C15+Assumptions!C22*Assumptions!C16,(Assumptions!C22*(Assumptions!C10*(1+Assumptions!C26)^(2-1)))*Assumptions!C15+Assumptions!C22*Assumptions!C16))+((Assumptions!C22*(Assumptions!C10*(1+Assumptions!C26)^(2-1)))*Assumptions!C18)+(Assumptions!C22*Assumptions!C19))+(Assumptions!C22*(Assumptions!C28+(Assumptions!C29-Assumptions!C28)*(2-1)/4)*Assumptions!C27)+((Assumptions!C31+Assumptions!C32+Assumptions!C33+Assumptions!C34)*(1+Assumptions!C35)^(2-1)+Assumptions!C30*(1+Assumptions!C36)^(2-1)) | F18: =((IF(Assumptions!D17=1,(((Assumptions!D22*(Assumptions!D10*(1+Assumptions!D26)^(2-1)))*(Assumptions!D11+Assumptions!D12))*(1-Assumptions!D20))*Assumptions!D15+Assumptions!D22*Assumptions!D16,(Assumptions!D22*(Assumptions!D10*(1+Assumptions!D26)^(2-1)))*Assumptions!D15+Assumptions!D22*Assumptions!D16))+((Assumptions!D22*(Assumptions!D10*(1+Assumptions!D26)^(2-1)))*Assumptions!D18)+(Assumptions!D22*Assumptions!D19))+(Assumptions!D22*(Assumptions!D28+(Assumptions!D29-Assumptions!D28)*(2-1)/4)*Assumptions!D27)+((Assumptions!D31+Assumptions!D32+Assumptions!D33+Assumptions!D34)*(1+Assumptions!D35)^(2-1)+Assumptions!D30*(1+Assumptions!D36)^(2-1)) | G18: =((IF(Assumptions!E17=1,(((Assumptions!E22*(Assumptions!E10*(1+Assumptions!E26)^(2-1)))*(Assumptions!E11+Assumptions!E12))*(1-Assumptions!E20))*Assumptions!E15+Assumptions!E22*Assumptions!E16,(Assumptions!E22*(Assumptions!E10*(1+Assumptions!E26)^(2-1)))*Assumptions!E15+Assumptions!E22*Assumptions!E16))+((Assumptions!E22*(Assumptions!E10*(1+Assumptions!E26)^(2-1)))*Assumptions!E18)+(Assumptions!E22*Assumptions!E19))+(Assumptions!E22*(Assumptions!E28+(Assumptions!E29-Assumptions!E28)*(2-1)/4)*Assumptions!E27)+((Assumptions!E31+Assumptions!E32+Assumptions!E33+Assumptions!E34)*(1+Assumptions!E35)^(2-1)+Assumptions!E30*(1+Assumptions!E36)^(2-1)) | H18: =((IF(Assumptions!C17=1,(((Assumptions!C23*(Assumptions!C10*(1+Assumptions!C26)^(3-1)))*(Assumptions!C11+Assumptions!C12))*(1-Assumptions!C20))*Assumptions!C15+Assumptions!C23*Assumptions!C16,(Assumptions!C23*(Assumptions!C10*(1+Assumptions!C26)^(3-1)))*Assumptions!C15+Assumptions!C23*Assumptions!C16))+((Assumptions!C23*(Assumptions!C10*(1+Assumptions!C26)^(3-1)))*Assumptions!C18)+(Assumptions!C23*Assumptions!C19))+(Assumptions!C23*(Assumptions!C28+(Assumptions!C29-Assumptions!C28)*(3-1)/4)*Assumptions!C27)+((Assumptions!C31+Assumptions!C32+Assumptions!C33+Assumptions!C34)*(1+Assumptions!C35)^(3-1)+Assumptions!C30*(1+Assumptions!C36)^(3-1)) | I18: =((IF(Assumptions!D17=1,(((Assumptions!D23*(Assumptions!D10*(1+Assumptions!D26)^(3-1)))*(Assumptions!D11+Assumptions!D12))*(1-Assumptions!D20))*Assumptions!D15+Assumptions!D23*Assumptions!D16,(Assumptions!D23*(Assumptions!D10*(1+Assumptions!D26)^(3-1)))*Assumptions!D15+Assumptions!D23*Assumptions!D16))+((Assumptions!D23*(Assumptions!D10*(1+Assumptions!D26)^(3-1)))*Assumptions!D18)+(Assumptions!D23*Assumptions!D19))+(Assumptions!D23*(Assumptions!D28+(Assumptions!D29-Assumptions!D28)*(3-1)/4)*Assumptions!D27)+((Assumptions!D31+Assumptions!D32+Assumptions!D33+Assumptions!D34)*(1+Assumptions!D35)^(3-1)+Assumptions!D30*(1+Assumptions!D36)^(3-1)) | J18: =((IF(Assumptions!E17=1,(((Assumptions!E23*(Assumptions!E10*(1+Assumptions!E26)^(3-1)))*(Assumptions!E11+Assumptions!E12))*(1-Assumptions!E20))*Assumptions!E15+Assumptions!E23*Assumptions!E16,(Assumptions!E23*(Assumptions!E10*(1+Assumptions!E26)^(3-1)))*Assumptions!E15+Assumptions!E23*Assumptions!E16))+((Assumptions!E23*(Assumptions!E10*(1+Assumptions!E26)^(3-1)))*Assumptions!E18)+(Assumptions!E23*Assumptions!E19))+(Assumptions!E23*(Assumptions!E28+(Assumptions!E29-Assumptions!E28)*(3-1)/4)*Assumptions!E27)+((Assumptions!E31+Assumptions!E32+Assumptions!E33+Assumptions!E34)*(1+Assumptions!E35)^(3-1)+Assumptions!E30*(1+Assumptions!E36)^(3-1)) | K18: =((IF(Assumptions!C17=1,(((Assumptions!C24*(Assumptions!C10*(1+Assumptions!C26)^(4-1)))*(Assumptions!C11+Assumptions!C12))*(1-Assumptions!C20))*Assumptions!C15+Assumptions!C24*Assumptions!C16,(Assumptions!C24*(Assumptions!C10*(1+Assumptions!C26)^(4-1)))*Assumptions!C15+Assumptions!C24*Assumptions!C16))+((Assumptions!C24*(Assumptions!C10*(1+Assumptions!C26)^(4-1)))*Assumptions!C18)+(Assumptions!C24*Assumptions!C19))+(Assumptions!C24*(Assumptions!C28+(Assumptions!C29-Assumptions!C28)*(4-1)/4)*Assumptions!C27)+((Assumptions!C31+Assumptions!C32+Assumptions!C33+Assumptions!C34)*(1+Assumptions!C35)^(4-1)+Assumptions!C30*(1+Assumptions!C36)^(4-1)) | L18: =((IF(Assumptions!D17=1,(((Assumptions!D24*(Assumptions!D10*(1+Assumptions!D26)^(4-1)))*(Assumptions!D11+Assumptions!D12))*(1-Assumptions!D20))*Assumptions!D15+Assumptions!D24*Assumptions!D16,(Assumptions!D24*(Assumptions!D10*(1+Assumptions!D26)^(4-1)))*Assumptions!D15+Assumptions!D24*Assumptions!D16))+((Assumptions!D24*(Assumptions!D10*(1+Assumptions!D26)^(4-1)))*Assumptions!D18)+(Assumptions!D24*Assumptions!D19))+(Assumptions!D24*(Assumptions!D28+(Assumptions!D29-Assumptions!D28)*(4-1)/4)*Assumptions!D27)+((Assumptions!D31+Assumptions!D32+Assumptions!D33+Assumptions!D34)*(1+Assumptions!D35)^(4-1)+Assumptions!D30*(1+Assumptions!D36)^(4-1)) | M18: =((IF(Assumptions!E17=1,(((Assumptions!E24*(Assumptions!E10*(1+Assumptions!E26)^(4-1)))*(Assumptions!E11+Assumptions!E12))*(1-Assumptions!E20))*Assumptions!E15+Assumptions!E24*Assumptions!E16,(Assumptions!E24*(Assumptions!E10*(1+Assumptions!E26)^(4-1)))*Assumptions!E15+Assumptions!E24*Assumptions!E16))+((Assumptions!E24*(Assumptions!E10*(1+Assumptions!E26)^(4-1)))*Assumptions!E18)+(Assumptions!E24*Assumptions!E19))+(Assumptions!E24*(Assumptions!E28+(Assumptions!E29-Assumptions!E28)*(4-1)/4)*Assumptions!E27)+((Assumptions!E31+Assumptions!E32+Assumptions!E33+Assumptions!E34)*(1+Assumptions!E35)^(4-1)+Assumptions!E30*(1+Assumptions!E36)^(4-1)) | N18: =((IF(Assumptions!C17=1,(((Assumptions!C25*(Assumptions!C10*(1+Assumptions!C26)^(5-1)))*(Assumptions!C11+Assumptions!C12))*(1-Assumptions!C20))*Assumptions!C15+Assumptions!C25*Assumptions!C16,(Assumptions!C25*(Assumptions!C10*(1+Assumptions!C26)^(5-1)))*Assumptions!C15+Assumptions!C25*Assumptions!C16))+((Assumptions!C25*(Assumptions!C10*(1+Assumptions!C26)^(5-1)))*Assumptions!C18)+(Assumptions!C25*Assumptions!C19))+(Assumptions!C25*(Assumptions!C28+(Assumptions!C29-Assumptions!C28)*(5-1)/4)*Assumptions!C27)+((Assumptions!C31+Assumptions!C32+Assumptions!C33+Assumptions!C34)*(1+Assumptions!C35)^(5-1)+Assumptions!C30*(1+Assumptions!C36)^(5-1)) | O18: =((IF(Assumptions!D17=1,(((Assumptions!D25*(Assumptions!D10*(1+Assumptions!D26)^(5-1)))*(Assumptions!D11+Assumptions!D12))*(1-Assumptions!D20))*Assumptions!D15+Assumptions!D25*Assumptions!D16,(Assumptions!D25*(Assumptions!D10*(1+Assumptions!D26)^(5-1)))*Assumptions!D15+Assumptions!D25*Assumptions!D16))+((Assumptions!D25*(Assumptions!D10*(1+Assumptions!D26)^(5-1)))*Assumptions!D18)+(Assumptions!D25*Assumptions!D19))+(Assumptions!D25*(Assumptions!D28+(Assumptions!D29-Assumptions!D28)*(5-1)/4)*Assumptions!D27)+((Assumptions!D31+Assumptions!D32+Assumptions!D33+Assumptions!D34)*(1+Assumptions!D35)^(5-1)+Assumptions!D30*(1+Assumptions!D36)^(5-1)) | P18: =((IF(Assumptions!E17=1,(((Assumptions!E25*(Assumptions!E10*(1+Assumptions!E26)^(5-1)))*(Assumptions!E11+Assumptions!E12))*(1-Assumptions!E20))*Assumptions!E15+Assumptions!E25*Assumptions!E16,(Assumptions!E25*(Assumptions!E10*(1+Assumptions!E26)^(5-1)))*Assumptions!E15+Assumptions!E25*Assumptions!E16))+((Assumptions!E25*(Assumptions!E10*(1+Assumptions!E26)^(5-1)))*Assumptions!E18)+(Assumptions!E25*Assumptions!E19))+(Assumptions!E25*(Assumptions!E28+(Assumptions!E29-Assumptions!E28)*(5-1)/4)*Assumptions!E27)+((Assumptions!E31+Assumptions!E32+Assumptions!E33+Assumptions!E34)*(1+Assumptions!E35)^(5-1)+Assumptions!E30*(1+Assumptions!E36)^(5-1))
A19: Net profit / (loss) ($) | B19: =(((((Assumptions!C21*(Assumptions!C10*(1+Assumptions!C26)^(1-1)))*(Assumptions!C11+Assumptions!C12))*(1-Assumptions!C20))-((IF(Assumptions!C17=1,(((Assumptions!C21*(Assumptions!C10*(1+Assumptions!C26)^(1-1)))*(Assumptions!C11+Assumptions!C12))*(1-Assumptions!C20))*Assumptions!C15+Assumptions!C21*Assumptions!C16,(Assumptions!C21*(Assumptions!C10*(1+Assumptions!C26)^(1-1)))*Assumptions!C15+Assumptions!C21*Assumptions!C16))+((Assumptions!C21*(Assumptions!C10*(1+Assumptions!C26)^(1-1)))*Assumptions!C18)+(Assumptions!C21*Assumptions!C19)))-(Assumptions!C21*(Assumptions!C28+(Assumptions!C29-Assumptions!C28)*(1-1)/4)*Assumptions!C27)-((Assumptions!C31+Assumptions!C32+Assumptions!C33+Assumptions!C34)*(1+Assumptions!C35)^(1-1)+Assumptions!C30*(1+Assumptions!C36)^(1-1))) | C19: =(((((Assumptions!D21*(Assumptions!D10*(1+Assumptions!D26)^(1-1)))*(Assumptions!D11+Assumptions!D12))*(1-Assumptions!D20))-((IF(Assumptions!D17=1,(((Assumptions!D21*(Assumptions!D10*(1+Assumptions!D26)^(1-1)))*(Assumptions!D11+Assumptions!D12))*(1-Assumptions!D20))*Assumptions!D15+Assumptions!D21*Assumptions!D16,(Assumptions!D21*(Assumptions!D10*(1+Assumptions!D26)^(1-1)))*Assumptions!D15+Assumptions!D21*Assumptions!D16))+((Assumptions!D21*(Assumptions!D10*(1+Assumptions!D26)^(1-1)))*Assumptions!D18)+(Assumptions!D21*Assumptions!D19)))-(Assumptions!D21*(Assumptions!D28+(Assumptions!D29-Assumptions!D28)*(1-1)/4)*Assumptions!D27)-((Assumptions!D31+Assumptions!D32+Assumptions!D33+Assumptions!D34)*(1+Assumptions!D35)^(1-1)+Assumptions!D30*(1+Assumptions!D36)^(1-1))) | D19: =(((((Assumptions!E21*(Assumptions!E10*(1+Assumptions!E26)^(1-1)))*(Assumptions!E11+Assumptions!E12))*(1-Assumptions!E20))-((IF(Assumptions!E17=1,(((Assumptions!E21*(Assumptions!E10*(1+Assumptions!E26)^(1-1)))*(Assumptions!E11+Assumptions!E12))*(1-Assumptions!E20))*Assumptions!E15+Assumptions!E21*Assumptions!E16,(Assumptions!E21*(Assumptions!E10*(1+Assumptions!E26)^(1-1)))*Assumptions!E15+Assumptions!E21*Assumptions!E16))+((Assumptions!E21*(Assumptions!E10*(1+Assumptions!E26)^(1-1)))*Assumptions!E18)+(Assumptions!E21*Assumptions!E19)))-(Assumptions!E21*(Assumptions!E28+(Assumptions!E29-Assumptions!E28)*(1-1)/4)*Assumptions!E27)-((Assumptions!E31+Assumptions!E32+Assumptions!E33+Assumptions!E34)*(1+Assumptions!E35)^(1-1)+Assumptions!E30*(1+Assumptions!E36)^(1-1))) | E19: =(((((Assumptions!C22*(Assumptions!C10*(1+Assumptions!C26)^(2-1)))*(Assumptions!C11+Assumptions!C12))*(1-Assumptions!C20))-((IF(Assumptions!C17=1,(((Assumptions!C22*(Assumptions!C10*(1+Assumptions!C26)^(2-1)))*(Assumptions!C11+Assumptions!C12))*(1-Assumptions!C20))*Assumptions!C15+Assumptions!C22*Assumptions!C16,(Assumptions!C22*(Assumptions!C10*(1+Assumptions!C26)^(2-1)))*Assumptions!C15+Assumptions!C22*Assumptions!C16))+((Assumptions!C22*(Assumptions!C10*(1+Assumptions!C26)^(2-1)))*Assumptions!C18)+(Assumptions!C22*Assumptions!C19)))-(Assumptions!C22*(Assumptions!C28+(Assumptions!C29-Assumptions!C28)*(2-1)/4)*Assumptions!C27)-((Assumptions!C31+Assumptions!C32+Assumptions!C33+Assumptions!C34)*(1+Assumptions!C35)^(2-1)+Assumptions!C30*(1+Assumptions!C36)^(2-1))) | F19: =(((((Assumptions!D22*(Assumptions!D10*(1+Assumptions!D26)^(2-1)))*(Assumptions!D11+Assumptions!D12))*(1-Assumptions!D20))-((IF(Assumptions!D17=1,(((Assumptions!D22*(Assumptions!D10*(1+Assumptions!D26)^(2-1)))*(Assumptions!D11+Assumptions!D12))*(1-Assumptions!D20))*Assumptions!D15+Assumptions!D22*Assumptions!D16,(Assumptions!D22*(Assumptions!D10*(1+Assumptions!D26)^(2-1)))*Assumptions!D15+Assumptions!D22*Assumptions!D16))+((Assumptions!D22*(Assumptions!D10*(1+Assumptions!D26)^(2-1)))*Assumptions!D18)+(Assumptions!D22*Assumptions!D19)))-(Assumptions!D22*(Assumptions!D28+(Assumptions!D29-Assumptions!D28)*(2-1)/4)*Assumptions!D27)-((Assumptions!D31+Assumptions!D32+Assumptions!D33+Assumptions!D34)*(1+Assumptions!D35)^(2-1)+Assumptions!D30*(1+Assumptions!D36)^(2-1))) | G19: =(((((Assumptions!E22*(Assumptions!E10*(1+Assumptions!E26)^(2-1)))*(Assumptions!E11+Assumptions!E12))*(1-Assumptions!E20))-((IF(Assumptions!E17=1,(((Assumptions!E22*(Assumptions!E10*(1+Assumptions!E26)^(2-1)))*(Assumptions!E11+Assumptions!E12))*(1-Assumptions!E20))*Assumptions!E15+Assumptions!E22*Assumptions!E16,(Assumptions!E22*(Assumptions!E10*(1+Assumptions!E26)^(2-1)))*Assumptions!E15+Assumptions!E22*Assumptions!E16))+((Assumptions!E22*(Assumptions!E10*(1+Assumptions!E26)^(2-1)))*Assumptions!E18)+(Assumptions!E22*Assumptions!E19)))-(Assumptions!E22*(Assumptions!E28+(Assumptions!E29-Assumptions!E28)*(2-1)/4)*Assumptions!E27)-((Assumptions!E31+Assumptions!E32+Assumptions!E33+Assumptions!E34)*(1+Assumptions!E35)^(2-1)+Assumptions!E30*(1+Assumptions!E36)^(2-1))) | H19: =(((((Assumptions!C23*(Assumptions!C10*(1+Assumptions!C26)^(3-1)))*(Assumptions!C11+Assumptions!C12))*(1-Assumptions!C20))-((IF(Assumptions!C17=1,(((Assumptions!C23*(Assumptions!C10*(1+Assumptions!C26)^(3-1)))*(Assumptions!C11+Assumptions!C12))*(1-Assumptions!C20))*Assumptions!C15+Assumptions!C23*Assumptions!C16,(Assumptions!C23*(Assumptions!C10*(1+Assumptions!C26)^(3-1)))*Assumptions!C15+Assumptions!C23*Assumptions!C16))+((Assumptions!C23*(Assumptions!C10*(1+Assumptions!C26)^(3-1)))*Assumptions!C18)+(Assumptions!C23*Assumptions!C19)))-(Assumptions!C23*(Assumptions!C28+(Assumptions!C29-Assumptions!C28)*(3-1)/4)*Assumptions!C27)-((Assumptions!C31+Assumptions!C32+Assumptions!C33+Assumptions!C34)*(1+Assumptions!C35)^(3-1)+Assumptions!C30*(1+Assumptions!C36)^(3-1))) | I19: =(((((Assumptions!D23*(Assumptions!D10*(1+Assumptions!D26)^(3-1)))*(Assumptions!D11+Assumptions!D12))*(1-Assumptions!D20))-((IF(Assumptions!D17=1,(((Assumptions!D23*(Assumptions!D10*(1+Assumptions!D26)^(3-1)))*(Assumptions!D11+Assumptions!D12))*(1-Assumptions!D20))*Assumptions!D15+Assumptions!D23*Assumptions!D16,(Assumptions!D23*(Assumptions!D10*(1+Assumptions!D26)^(3-1)))*Assumptions!D15+Assumptions!D23*Assumptions!D16))+((Assumptions!D23*(Assumptions!D10*(1+Assumptions!D26)^(3-1)))*Assumptions!D18)+(Assumptions!D23*Assumptions!D19)))-(Assumptions!D23*(Assumptions!D28+(Assumptions!D29-Assumptions!D28)*(3-1)/4)*Assumptions!D27)-((Assumptions!D31+Assumptions!D32+Assumptions!D33+Assumptions!D34)*(1+Assumptions!D35)^(3-1)+Assumptions!D30*(1+Assumptions!D36)^(3-1))) | J19: =(((((Assumptions!E23*(Assumptions!E10*(1+Assumptions!E26)^(3-1)))*(Assumptions!E11+Assumptions!E12))*(1-Assumptions!E20))-((IF(Assumptions!E17=1,(((Assumptions!E23*(Assumptions!E10*(1+Assumptions!E26)^(3-1)))*(Assumptions!E11+Assumptions!E12))*(1-Assumptions!E20))*Assumptions!E15+Assumptions!E23*Assumptions!E16,(Assumptions!E23*(Assumptions!E10*(1+Assumptions!E26)^(3-1)))*Assumptions!E15+Assumptions!E23*Assumptions!E16))+((Assumptions!E23*(Assumptions!E10*(1+Assumptions!E26)^(3-1)))*Assumptions!E18)+(Assumptions!E23*Assumptions!E19)))-(Assumptions!E23*(Assumptions!E28+(Assumptions!E29-Assumptions!E28)*(3-1)/4)*Assumptions!E27)-((Assumptions!E31+Assumptions!E32+Assumptions!E33+Assumptions!E34)*(1+Assumptions!E35)^(3-1)+Assumptions!E30*(1+Assumptions!E36)^(3-1))) | K19: =(((((Assumptions!C24*(Assumptions!C10*(1+Assumptions!C26)^(4-1)))*(Assumptions!C11+Assumptions!C12))*(1-Assumptions!C20))-((IF(Assumptions!C17=1,(((Assumptions!C24*(Assumptions!C10*(1+Assumptions!C26)^(4-1)))*(Assumptions!C11+Assumptions!C12))*(1-Assumptions!C20))*Assumptions!C15+Assumptions!C24*Assumptions!C16,(Assumptions!C24*(Assumptions!C10*(1+Assumptions!C26)^(4-1)))*Assumptions!C15+Assumptions!C24*Assumptions!C16))+((Assumptions!C24*(Assumptions!C10*(1+Assumptions!C26)^(4-1)))*Assumptions!C18)+(Assumptions!C24*Assumptions!C19)))-(Assumptions!C24*(Assumptions!C28+(Assumptions!C29-Assumptions!C28)*(4-1)/4)*Assumptions!C27)-((Assumptions!C31+Assumptions!C32+Assumptions!C33+Assumptions!C34)*(1+Assumptions!C35)^(4-1)+Assumptions!C30*(1+Assumptions!C36)^(4-1))) | L19: =(((((Assumptions!D24*(Assumptions!D10*(1+Assumptions!D26)^(4-1)))*(Assumptions!D11+Assumptions!D12))*(1-Assumptions!D20))-((IF(Assumptions!D17=1,(((Assumptions!D24*(Assumptions!D10*(1+Assumptions!D26)^(4-1)))*(Assumptions!D11+Assumptions!D12))*(1-Assumptions!D20))*Assumptions!D15+Assumptions!D24*Assumptions!D16,(Assumptions!D24*(Assumptions!D10*(1+Assumptions!D26)^(4-1)))*Assumptions!D15+Assumptions!D24*Assumptions!D16))+((Assumptions!D24*(Assumptions!D10*(1+Assumptions!D26)^(4-1)))*Assumptions!D18)+(Assumptions!D24*Assumptions!D19)))-(Assumptions!D24*(Assumptions!D28+(Assumptions!D29-Assumptions!D28)*(4-1)/4)*Assumptions!D27)-((Assumptions!D31+Assumptions!D32+Assumptions!D33+Assumptions!D34)*(1+Assumptions!D35)^(4-1)+Assumptions!D30*(1+Assumptions!D36)^(4-1))) | M19: =(((((Assumptions!E24*(Assumptions!E10*(1+Assumptions!E26)^(4-1)))*(Assumptions!E11+Assumptions!E12))*(1-Assumptions!E20))-((IF(Assumptions!E17=1,(((Assumptions!E24*(Assumptions!E10*(1+Assumptions!E26)^(4-1)))*(Assumptions!E11+Assumptions!E12))*(1-Assumptions!E20))*Assumptions!E15+Assumptions!E24*Assumptions!E16,(Assumptions!E24*(Assumptions!E10*(1+Assumptions!E26)^(4-1)))*Assumptions!E15+Assumptions!E24*Assumptions!E16))+((Assumptions!E24*(Assumptions!E10*(1+Assumptions!E26)^(4-1)))*Assumptions!E18)+(Assumptions!E24*Assumptions!E19)))-(Assumptions!E24*(Assumptions!E28+(Assumptions!E29-Assumptions!E28)*(4-1)/4)*Assumptions!E27)-((Assumptions!E31+Assumptions!E32+Assumptions!E33+Assumptions!E34)*(1+Assumptions!E35)^(4-1)+Assumptions!E30*(1+Assumptions!E36)^(4-1))) | N19: =(((((Assumptions!C25*(Assumptions!C10*(1+Assumptions!C26)^(5-1)))*(Assumptions!C11+Assumptions!C12))*(1-Assumptions!C20))-((IF(Assumptions!C17=1,(((Assumptions!C25*(Assumptions!C10*(1+Assumptions!C26)^(5-1)))*(Assumptions!C11+Assumptions!C12))*(1-Assumptions!C20))*Assumptions!C15+Assumptions!C25*Assumptions!C16,(Assumptions!C25*(Assumptions!C10*(1+Assumptions!C26)^(5-1)))*Assumptions!C15+Assumptions!C25*Assumptions!C16))+((Assumptions!C25*(Assumptions!C10*(1+Assumptions!C26)^(5-1)))*Assumptions!C18)+(Assumptions!C25*Assumptions!C19)))-(Assumptions!C25*(Assumptions!C28+(Assumptions!C29-Assumptions!C28)*(5-1)/4)*Assumptions!C27)-((Assumptions!C31+Assumptions!C32+Assumptions!C33+Assumptions!C34)*(1+Assumptions!C35)^(5-1)+Assumptions!C30*(1+Assumptions!C36)^(5-1))) | O19: =(((((Assumptions!D25*(Assumptions!D10*(1+Assumptions!D26)^(5-1)))*(Assumptions!D11+Assumptions!D12))*(1-Assumptions!D20))-((IF(Assumptions!D17=1,(((Assumptions!D25*(Assumptions!D10*(1+Assumptions!D26)^(5-1)))*(Assumptions!D11+Assumptions!D12))*(1-Assumptions!D20))*Assumptions!D15+Assumptions!D25*Assumptions!D16,(Assumptions!D25*(Assumptions!D10*(1+Assumptions!D26)^(5-1)))*Assumptions!D15+Assumptions!D25*Assumptions!D16))+((Assumptions!D25*(Assumptions!D10*(1+Assumptions!D26)^(5-1)))*Assumptions!D18)+(Assumptions!D25*Assumptions!D19)))-(Assumptions!D25*(Assumptions!D28+(Assumptions!D29-Assumptions!D28)*(5-1)/4)*Assumptions!D27)-((Assumptions!D31+Assumptions!D32+Assumptions!D33+Assumptions!D34)*(1+Assumptions!D35)^(5-1)+Assumptions!D30*(1+Assumptions!D36)^(5-1))) | P19: =(((((Assumptions!E25*(Assumptions!E10*(1+Assumptions!E26)^(5-1)))*(Assumptions!E11+Assumptions!E12))*(1-Assumptions!E20))-((IF(Assumptions!E17=1,(((Assumptions!E25*(Assumptions!E10*(1+Assumptions!E26)^(5-1)))*(Assumptions!E11+Assumptions!E12))*(1-Assumptions!E20))*Assumptions!E15+Assumptions!E25*Assumptions!E16,(Assumptions!E25*(Assumptions!E10*(1+Assumptions!E26)^(5-1)))*Assumptions!E15+Assumptions!E25*Assumptions!E16))+((Assumptions!E25*(Assumptions!E10*(1+Assumptions!E26)^(5-1)))*Assumptions!E18)+(Assumptions!E25*Assumptions!E19)))-(Assumptions!E25*(Assumptions!E28+(Assumptions!E29-Assumptions!E28)*(5-1)/4)*Assumptions!E27)-((Assumptions!E31+Assumptions!E32+Assumptions!E33+Assumptions!E34)*(1+Assumptions!E35)^(5-1)+Assumptions!E30*(1+Assumptions!E36)^(5-1)))
